[2025-06-12T01:02:58.809+0000] {taskinstance.py:1956} INFO - Dependencies all met for dep_context=non-requeueable deps ti=<TaskInstance: dynamic_training_pipeline.train_random_forest manual__2025-06-12T01:02:52.793534+00:00 [queued]>
[2025-06-12T01:02:58.813+0000] {taskinstance.py:1956} INFO - Dependencies all met for dep_context=requeueable deps ti=<TaskInstance: dynamic_training_pipeline.train_random_forest manual__2025-06-12T01:02:52.793534+00:00 [queued]>
[2025-06-12T01:02:58.813+0000] {taskinstance.py:2170} INFO - Starting attempt 1 of 2
[2025-06-12T01:02:58.818+0000] {taskinstance.py:2191} INFO - Executing <Task(PythonOperator): train_random_forest> on 2025-06-12 01:02:52.793534+00:00
[2025-06-12T01:02:58.821+0000] {standard_task_runner.py:60} INFO - Started process 310 to run task
[2025-06-12T01:02:58.823+0000] {standard_task_runner.py:87} INFO - Running: ['***', 'tasks', 'run', 'dynamic_training_pipeline', 'train_random_forest', 'manual__2025-06-12T01:02:52.793534+00:00', '--job-id', '90', '--raw', '--subdir', 'DAGS_FOLDER/dag_dynamic.py', '--cfg-path', '/tmp/tmpkc45nt0v']
[2025-06-12T01:02:58.826+0000] {standard_task_runner.py:88} INFO - Job 90: Subtask train_random_forest
[2025-06-12T01:02:58.847+0000] {task_command.py:423} INFO - Running <TaskInstance: dynamic_training_pipeline.train_random_forest manual__2025-06-12T01:02:52.793534+00:00 [running]> on host 27920052c294
[2025-06-12T01:02:58.878+0000] {taskinstance.py:2480} INFO - Exporting env vars: AIRFLOW_CTX_DAG_OWNER='***' AIRFLOW_CTX_DAG_ID='dynamic_training_pipeline' AIRFLOW_CTX_TASK_ID='train_random_forest' AIRFLOW_CTX_EXECUTION_DATE='2025-06-12T01:02:52.793534+00:00' AIRFLOW_CTX_TRY_NUMBER='1' AIRFLOW_CTX_DAG_RUN_ID='manual__2025-06-12T01:02:52.793534+00:00'
[2025-06-12T01:02:58.880+0000] {taskinstance.py:2698} ERROR - Task failed with exception
Traceback (most recent call last):
  File "/home/airflow/.local/lib/python3.10/site-packages/airflow/models/taskinstance.py", line 433, in _execute_task
    result = execute_callable(context=context, **execute_callable_kwargs)
  File "/home/airflow/.local/lib/python3.10/site-packages/airflow/operators/python.py", line 199, in execute
    return_value = self.execute_callable()
  File "/home/airflow/.local/lib/python3.10/site-packages/airflow/operators/python.py", line 216, in execute_callable
    return self.python_callable(*self.op_args, **self.op_kwargs)
TypeError: train_model() missing 2 required positional arguments: 'model' and 'target_col'
[2025-06-12T01:02:58.883+0000] {taskinstance.py:1138} INFO - Marking task as UP_FOR_RETRY. dag_id=dynamic_training_pipeline, task_id=train_random_forest, execution_date=20250612T010252, start_date=20250612T010258, end_date=20250612T010258
[2025-06-12T01:02:58.887+0000] {standard_task_runner.py:107} ERROR - Failed to execute job 90 for task train_random_forest (train_model() missing 2 required positional arguments: 'model' and 'target_col'; 310)
[2025-06-12T01:02:58.922+0000] {local_task_job_runner.py:234} INFO - Task exited with return code 1
[2025-06-12T01:02:58.931+0000] {taskinstance.py:3280} INFO - 0 downstream tasks scheduled from follow-on schedule check
