[2025-06-12T01:02:58.817+0000] {taskinstance.py:1956} INFO - Dependencies all met for dep_context=non-requeueable deps ti=<TaskInstance: dynamic_training_pipeline.train_logistic_regression manual__2025-06-12T01:02:52.793534+00:00 [queued]>
[2025-06-12T01:02:58.822+0000] {taskinstance.py:1956} INFO - Dependencies all met for dep_context=requeueable deps ti=<TaskInstance: dynamic_training_pipeline.train_logistic_regression manual__2025-06-12T01:02:52.793534+00:00 [queued]>
[2025-06-12T01:02:58.823+0000] {taskinstance.py:2170} INFO - Starting attempt 1 of 2
[2025-06-12T01:02:58.828+0000] {taskinstance.py:2191} INFO - Executing <Task(PythonOperator): train_logistic_regression> on 2025-06-12 01:02:52.793534+00:00
[2025-06-12T01:02:58.831+0000] {standard_task_runner.py:60} INFO - Started process 311 to run task
[2025-06-12T01:02:58.833+0000] {standard_task_runner.py:87} INFO - Running: ['***', 'tasks', 'run', 'dynamic_training_pipeline', 'train_logistic_regression', 'manual__2025-06-12T01:02:52.793534+00:00', '--job-id', '91', '--raw', '--subdir', 'DAGS_FOLDER/dag_dynamic.py', '--cfg-path', '/tmp/tmppum1jsdj']
[2025-06-12T01:02:58.834+0000] {standard_task_runner.py:88} INFO - Job 91: Subtask train_logistic_regression
[2025-06-12T01:02:58.856+0000] {task_command.py:423} INFO - Running <TaskInstance: dynamic_training_pipeline.train_logistic_regression manual__2025-06-12T01:02:52.793534+00:00 [running]> on host 27920052c294
[2025-06-12T01:02:58.886+0000] {taskinstance.py:2480} INFO - Exporting env vars: AIRFLOW_CTX_DAG_OWNER='***' AIRFLOW_CTX_DAG_ID='dynamic_training_pipeline' AIRFLOW_CTX_TASK_ID='train_logistic_regression' AIRFLOW_CTX_EXECUTION_DATE='2025-06-12T01:02:52.793534+00:00' AIRFLOW_CTX_TRY_NUMBER='1' AIRFLOW_CTX_DAG_RUN_ID='manual__2025-06-12T01:02:52.793534+00:00'
[2025-06-12T01:02:58.886+0000] {taskinstance.py:2698} ERROR - Task failed with exception
Traceback (most recent call last):
  File "/home/airflow/.local/lib/python3.10/site-packages/airflow/models/taskinstance.py", line 433, in _execute_task
    result = execute_callable(context=context, **execute_callable_kwargs)
  File "/home/airflow/.local/lib/python3.10/site-packages/airflow/operators/python.py", line 199, in execute
    return_value = self.execute_callable()
  File "/home/airflow/.local/lib/python3.10/site-packages/airflow/operators/python.py", line 216, in execute_callable
    return self.python_callable(*self.op_args, **self.op_kwargs)
TypeError: train_model() missing 2 required positional arguments: 'model' and 'target_col'
[2025-06-12T01:02:58.890+0000] {taskinstance.py:1138} INFO - Marking task as UP_FOR_RETRY. dag_id=dynamic_training_pipeline, task_id=train_logistic_regression, execution_date=20250612T010252, start_date=20250612T010258, end_date=20250612T010258
[2025-06-12T01:02:58.894+0000] {standard_task_runner.py:107} ERROR - Failed to execute job 91 for task train_logistic_regression (train_model() missing 2 required positional arguments: 'model' and 'target_col'; 311)
[2025-06-12T01:02:58.930+0000] {local_task_job_runner.py:234} INFO - Task exited with return code 1
[2025-06-12T01:02:58.941+0000] {taskinstance.py:3280} INFO - 0 downstream tasks scheduled from follow-on schedule check
