[2025-06-12T01:45:49.849+0000] {taskinstance.py:1956} INFO - Dependencies all met for dep_context=non-requeueable deps ti=<TaskInstance: dynamic_training_pipeline.train_logistic_regression scheduled__2024-12-05T15:00:00+00:00 [queued]>
[2025-06-12T01:45:49.905+0000] {taskinstance.py:1956} INFO - Dependencies all met for dep_context=requeueable deps ti=<TaskInstance: dynamic_training_pipeline.train_logistic_regression scheduled__2024-12-05T15:00:00+00:00 [queued]>
[2025-06-12T01:45:49.910+0000] {taskinstance.py:2170} INFO - Starting attempt 1 of 2
[2025-06-12T01:45:49.969+0000] {taskinstance.py:2191} INFO - Executing <Task(PythonOperator): train_logistic_regression> on 2024-12-05 15:00:00+00:00
[2025-06-12T01:45:50.068+0000] {standard_task_runner.py:60} INFO - Started process 907 to run task
[2025-06-12T01:45:50.123+0000] {standard_task_runner.py:87} INFO - Running: ['***', 'tasks', 'run', 'dynamic_training_pipeline', 'train_logistic_regression', 'scheduled__2024-12-05T15:00:00+00:00', '--job-id', '44', '--raw', '--subdir', 'DAGS_FOLDER/dag_dynamic.py', '--cfg-path', '/tmp/tmp1gtznntz']
[2025-06-12T01:45:50.141+0000] {standard_task_runner.py:88} INFO - Job 44: Subtask train_logistic_regression
[2025-06-12T01:45:50.361+0000] {task_command.py:423} INFO - Running <TaskInstance: dynamic_training_pipeline.train_logistic_regression scheduled__2024-12-05T15:00:00+00:00 [running]> on host caffbd336f08
[2025-06-12T01:45:50.600+0000] {taskinstance.py:2480} INFO - Exporting env vars: AIRFLOW_CTX_DAG_OWNER='***' AIRFLOW_CTX_DAG_ID='dynamic_training_pipeline' AIRFLOW_CTX_TASK_ID='train_logistic_regression' AIRFLOW_CTX_EXECUTION_DATE='2024-12-05T15:00:00+00:00' AIRFLOW_CTX_TRY_NUMBER='1' AIRFLOW_CTX_DAG_RUN_ID='scheduled__2024-12-05T15:00:00+00:00'
[2025-06-12T01:45:50.606+0000] {taskinstance.py:2698} ERROR - Task failed with exception
Traceback (most recent call last):
  File "/home/airflow/.local/lib/python3.10/site-packages/airflow/models/taskinstance.py", line 433, in _execute_task
    result = execute_callable(context=context, **execute_callable_kwargs)
  File "/home/airflow/.local/lib/python3.10/site-packages/airflow/operators/python.py", line 199, in execute
    return_value = self.execute_callable()
  File "/home/airflow/.local/lib/python3.10/site-packages/airflow/operators/python.py", line 216, in execute_callable
    return self.python_callable(*self.op_args, **self.op_kwargs)
  File "/opt/airflow/dags/hiring_dynamic_functions.py", line 112, in train_model
    raise FileNotFoundError(f"train.html no encontrado en: {train_html}")
FileNotFoundError: train.html no encontrado en: /opt/***/dags/2024-12-05/splits/train.html
[2025-06-12T01:45:50.640+0000] {taskinstance.py:1138} INFO - Marking task as UP_FOR_RETRY. dag_id=dynamic_training_pipeline, task_id=train_logistic_regression, execution_date=20241205T150000, start_date=20250612T014549, end_date=20250612T014550
[2025-06-12T01:45:50.660+0000] {standard_task_runner.py:107} ERROR - Failed to execute job 44 for task train_logistic_regression (train.html no encontrado en: /opt/***/dags/2024-12-05/splits/train.html; 907)
[2025-06-12T01:45:50.688+0000] {local_task_job_runner.py:234} INFO - Task exited with return code 1
[2025-06-12T01:45:50.750+0000] {taskinstance.py:3280} INFO - 0 downstream tasks scheduled from follow-on schedule check
