[2025-06-12T01:45:52.392+0000] {taskinstance.py:1956} INFO - Dependencies all met for dep_context=non-requeueable deps ti=<TaskInstance: dynamic_training_pipeline.train_logistic_regression scheduled__2025-01-05T15:00:00+00:00 [queued]>
[2025-06-12T01:45:52.409+0000] {taskinstance.py:1956} INFO - Dependencies all met for dep_context=requeueable deps ti=<TaskInstance: dynamic_training_pipeline.train_logistic_regression scheduled__2025-01-05T15:00:00+00:00 [queued]>
[2025-06-12T01:45:52.411+0000] {taskinstance.py:2170} INFO - Starting attempt 1 of 2
[2025-06-12T01:45:52.433+0000] {taskinstance.py:2191} INFO - Executing <Task(PythonOperator): train_logistic_regression> on 2025-01-05 15:00:00+00:00
[2025-06-12T01:45:52.440+0000] {standard_task_runner.py:60} INFO - Started process 1015 to run task
[2025-06-12T01:45:52.446+0000] {standard_task_runner.py:87} INFO - Running: ['***', 'tasks', 'run', 'dynamic_training_pipeline', 'train_logistic_regression', 'scheduled__2025-01-05T15:00:00+00:00', '--job-id', '64', '--raw', '--subdir', 'DAGS_FOLDER/dag_dynamic.py', '--cfg-path', '/tmp/tmpr033sryy']
[2025-06-12T01:45:52.449+0000] {standard_task_runner.py:88} INFO - Job 64: Subtask train_logistic_regression
[2025-06-12T01:45:52.500+0000] {task_command.py:423} INFO - Running <TaskInstance: dynamic_training_pipeline.train_logistic_regression scheduled__2025-01-05T15:00:00+00:00 [running]> on host caffbd336f08
[2025-06-12T01:45:52.558+0000] {taskinstance.py:2480} INFO - Exporting env vars: AIRFLOW_CTX_DAG_OWNER='***' AIRFLOW_CTX_DAG_ID='dynamic_training_pipeline' AIRFLOW_CTX_TASK_ID='train_logistic_regression' AIRFLOW_CTX_EXECUTION_DATE='2025-01-05T15:00:00+00:00' AIRFLOW_CTX_TRY_NUMBER='1' AIRFLOW_CTX_DAG_RUN_ID='scheduled__2025-01-05T15:00:00+00:00'
[2025-06-12T01:45:52.559+0000] {taskinstance.py:2698} ERROR - Task failed with exception
Traceback (most recent call last):
  File "/home/airflow/.local/lib/python3.10/site-packages/airflow/models/taskinstance.py", line 433, in _execute_task
    result = execute_callable(context=context, **execute_callable_kwargs)
  File "/home/airflow/.local/lib/python3.10/site-packages/airflow/operators/python.py", line 199, in execute
    return_value = self.execute_callable()
  File "/home/airflow/.local/lib/python3.10/site-packages/airflow/operators/python.py", line 216, in execute_callable
    return self.python_callable(*self.op_args, **self.op_kwargs)
  File "/opt/airflow/dags/hiring_dynamic_functions.py", line 112, in train_model
    raise FileNotFoundError(f"train.html no encontrado en: {train_html}")
FileNotFoundError: train.html no encontrado en: /opt/***/dags/2025-01-05/splits/train.html
[2025-06-12T01:45:52.565+0000] {taskinstance.py:1138} INFO - Marking task as UP_FOR_RETRY. dag_id=dynamic_training_pipeline, task_id=train_logistic_regression, execution_date=20250105T150000, start_date=20250612T014552, end_date=20250612T014552
[2025-06-12T01:45:52.571+0000] {standard_task_runner.py:107} ERROR - Failed to execute job 64 for task train_logistic_regression (train.html no encontrado en: /opt/***/dags/2025-01-05/splits/train.html; 1015)
[2025-06-12T01:45:52.587+0000] {local_task_job_runner.py:234} INFO - Task exited with return code 1
[2025-06-12T01:45:52.604+0000] {taskinstance.py:3280} INFO - 0 downstream tasks scheduled from follow-on schedule check
