[2025-06-12T01:50:55.703+0000] {taskinstance.py:1956} INFO - Dependencies all met for dep_context=non-requeueable deps ti=<TaskInstance: dynamic_training_pipeline.train_xgboost scheduled__2025-03-05T15:00:00+00:00 [queued]>
[2025-06-12T01:50:55.711+0000] {taskinstance.py:1956} INFO - Dependencies all met for dep_context=requeueable deps ti=<TaskInstance: dynamic_training_pipeline.train_xgboost scheduled__2025-03-05T15:00:00+00:00 [queued]>
[2025-06-12T01:50:55.711+0000] {taskinstance.py:2170} INFO - Starting attempt 2 of 2
[2025-06-12T01:50:55.724+0000] {taskinstance.py:2191} INFO - Executing <Task(PythonOperator): train_xgboost> on 2025-03-05 15:00:00+00:00
[2025-06-12T01:50:55.730+0000] {standard_task_runner.py:60} INFO - Started process 1590 to run task
[2025-06-12T01:50:55.732+0000] {standard_task_runner.py:87} INFO - Running: ['***', 'tasks', 'run', 'dynamic_training_pipeline', 'train_xgboost', 'scheduled__2025-03-05T15:00:00+00:00', '--job-id', '82', '--raw', '--subdir', 'DAGS_FOLDER/dag_dynamic.py', '--cfg-path', '/tmp/tmp0clyrhxs']
[2025-06-12T01:50:55.734+0000] {standard_task_runner.py:88} INFO - Job 82: Subtask train_xgboost
[2025-06-12T01:50:55.778+0000] {task_command.py:423} INFO - Running <TaskInstance: dynamic_training_pipeline.train_xgboost scheduled__2025-03-05T15:00:00+00:00 [running]> on host caffbd336f08
[2025-06-12T01:50:55.844+0000] {taskinstance.py:2480} INFO - Exporting env vars: AIRFLOW_CTX_DAG_OWNER='***' AIRFLOW_CTX_DAG_ID='dynamic_training_pipeline' AIRFLOW_CTX_TASK_ID='train_xgboost' AIRFLOW_CTX_EXECUTION_DATE='2025-03-05T15:00:00+00:00' AIRFLOW_CTX_TRY_NUMBER='2' AIRFLOW_CTX_DAG_RUN_ID='scheduled__2025-03-05T15:00:00+00:00'
[2025-06-12T01:50:55.846+0000] {taskinstance.py:2698} ERROR - Task failed with exception
Traceback (most recent call last):
  File "/home/airflow/.local/lib/python3.10/site-packages/airflow/models/taskinstance.py", line 433, in _execute_task
    result = execute_callable(context=context, **execute_callable_kwargs)
  File "/home/airflow/.local/lib/python3.10/site-packages/airflow/operators/python.py", line 199, in execute
    return_value = self.execute_callable()
  File "/home/airflow/.local/lib/python3.10/site-packages/airflow/operators/python.py", line 216, in execute_callable
    return self.python_callable(*self.op_args, **self.op_kwargs)
  File "/opt/airflow/dags/hiring_dynamic_functions.py", line 112, in train_model
    raise FileNotFoundError(f"train.html no encontrado en: {train_html}")
FileNotFoundError: train.html no encontrado en: /opt/***/dags/2025-03-05/splits/train.html
[2025-06-12T01:50:55.854+0000] {taskinstance.py:1138} INFO - Marking task as FAILED. dag_id=dynamic_training_pipeline, task_id=train_xgboost, execution_date=20250305T150000, start_date=20250612T015055, end_date=20250612T015055
[2025-06-12T01:50:55.862+0000] {standard_task_runner.py:107} ERROR - Failed to execute job 82 for task train_xgboost (train.html no encontrado en: /opt/***/dags/2025-03-05/splits/train.html; 1590)
[2025-06-12T01:50:55.874+0000] {local_task_job_runner.py:234} INFO - Task exited with return code 1
[2025-06-12T01:50:55.892+0000] {taskinstance.py:3280} INFO - 0 downstream tasks scheduled from follow-on schedule check
