[2025-06-12T01:50:54.091+0000] {taskinstance.py:1956} INFO - Dependencies all met for dep_context=non-requeueable deps ti=<TaskInstance: dynamic_training_pipeline.train_logistic_regression scheduled__2025-04-05T15:00:00+00:00 [queued]>
[2025-06-12T01:50:54.098+0000] {taskinstance.py:1956} INFO - Dependencies all met for dep_context=requeueable deps ti=<TaskInstance: dynamic_training_pipeline.train_logistic_regression scheduled__2025-04-05T15:00:00+00:00 [queued]>
[2025-06-12T01:50:54.099+0000] {taskinstance.py:2170} INFO - Starting attempt 2 of 2
[2025-06-12T01:50:54.108+0000] {taskinstance.py:2191} INFO - Executing <Task(PythonOperator): train_logistic_regression> on 2025-04-05 15:00:00+00:00
[2025-06-12T01:50:54.112+0000] {standard_task_runner.py:60} INFO - Started process 1501 to run task
[2025-06-12T01:50:54.115+0000] {standard_task_runner.py:87} INFO - Running: ['***', 'tasks', 'run', 'dynamic_training_pipeline', 'train_logistic_regression', 'scheduled__2025-04-05T15:00:00+00:00', '--job-id', '81', '--raw', '--subdir', 'DAGS_FOLDER/dag_dynamic.py', '--cfg-path', '/tmp/tmpjw53pkaf']
[2025-06-12T01:50:54.117+0000] {standard_task_runner.py:88} INFO - Job 81: Subtask train_logistic_regression
[2025-06-12T01:50:54.149+0000] {task_command.py:423} INFO - Running <TaskInstance: dynamic_training_pipeline.train_logistic_regression scheduled__2025-04-05T15:00:00+00:00 [running]> on host caffbd336f08
[2025-06-12T01:50:54.186+0000] {taskinstance.py:2480} INFO - Exporting env vars: AIRFLOW_CTX_DAG_OWNER='***' AIRFLOW_CTX_DAG_ID='dynamic_training_pipeline' AIRFLOW_CTX_TASK_ID='train_logistic_regression' AIRFLOW_CTX_EXECUTION_DATE='2025-04-05T15:00:00+00:00' AIRFLOW_CTX_TRY_NUMBER='2' AIRFLOW_CTX_DAG_RUN_ID='scheduled__2025-04-05T15:00:00+00:00'
[2025-06-12T01:50:54.190+0000] {taskinstance.py:2698} ERROR - Task failed with exception
Traceback (most recent call last):
  File "/home/airflow/.local/lib/python3.10/site-packages/airflow/models/taskinstance.py", line 433, in _execute_task
    result = execute_callable(context=context, **execute_callable_kwargs)
  File "/home/airflow/.local/lib/python3.10/site-packages/airflow/operators/python.py", line 199, in execute
    return_value = self.execute_callable()
  File "/home/airflow/.local/lib/python3.10/site-packages/airflow/operators/python.py", line 216, in execute_callable
    return self.python_callable(*self.op_args, **self.op_kwargs)
  File "/opt/airflow/dags/hiring_dynamic_functions.py", line 112, in train_model
    raise FileNotFoundError(f"train.html no encontrado en: {train_html}")
FileNotFoundError: train.html no encontrado en: /opt/***/dags/2025-04-05/splits/train.html
[2025-06-12T01:50:54.193+0000] {taskinstance.py:1138} INFO - Marking task as FAILED. dag_id=dynamic_training_pipeline, task_id=train_logistic_regression, execution_date=20250405T150000, start_date=20250612T015054, end_date=20250612T015054
[2025-06-12T01:50:54.198+0000] {standard_task_runner.py:107} ERROR - Failed to execute job 81 for task train_logistic_regression (train.html no encontrado en: /opt/***/dags/2025-04-05/splits/train.html; 1501)
[2025-06-12T01:50:54.212+0000] {local_task_job_runner.py:234} INFO - Task exited with return code 1
[2025-06-12T01:50:54.222+0000] {taskinstance.py:3280} INFO - 0 downstream tasks scheduled from follow-on schedule check
